[32m2024-11-30 15:37:27 -0800[0m - dagster - [34mDEBUG[0m - __ASSET_JOB - 829f858d-6ad0-4c30-b6a0-0874106ff019 - 37499 - LOGS_CAPTURED - Started capturing logs in process (pid: 37499).
[32m2024-11-30 15:37:27 -0800[0m - dagster - [34mDEBUG[0m - __ASSET_JOB - 829f858d-6ad0-4c30-b6a0-0874106ff019 - 37499 - manhattan_map - STEP_START - Started execution of step "manhattan_map".
[32m2024-11-30 15:37:30 -0800[0m - dagster - [34mERROR[0m - [31m__ASSET_JOB - 829f858d-6ad0-4c30-b6a0-0874106ff019 - 37499 - manhattan_map - STEP_FAILURE - Execution of step "manhattan_map" failed.

dagster._core.errors.DagsterExecutionStepExecutionError: Error occurred while executing op "manhattan_map"::

ValueError: 
Image export using the "kaleido" engine requires the kaleido package,
which can be installed using pip:
    $ pip install -U kaleido


Stack Trace:
  File "/Users/jairusmartinez/Documents/Python_Data_Analysis/dagsteru/.venv/lib/python3.12/site-packages/dagster/_core/execution/plan/utils.py", line 54, in op_execution_error_boundary
    yield
  File "/Users/jairusmartinez/Documents/Python_Data_Analysis/dagsteru/.venv/lib/python3.12/site-packages/dagster/_utils/__init__.py", line 482, in iterate_with_context
    next_output = next(iterator)
                  ^^^^^^^^^^^^^^
  File "/Users/jairusmartinez/Documents/Python_Data_Analysis/dagsteru/.venv/lib/python3.12/site-packages/dagster/_core/execution/plan/compute_generator.py", line 140, in _coerce_op_compute_fn_to_iterator
    result = invoke_compute_fn(
             ^^^^^^^^^^^^^^^^^^
  File "/Users/jairusmartinez/Documents/Python_Data_Analysis/dagsteru/.venv/lib/python3.12/site-packages/dagster/_core/execution/plan/compute_generator.py", line 128, in invoke_compute_fn
    return fn(context, **args_to_pass) if context_arg_provided else fn(**args_to_pass)
                                                                    ^^^^^^^^^^^^^^^^^^
  File "/Users/jairusmartinez/Documents/Python_Data_Analysis/dagsteru/dagster_university/dagster_university/assets/metrics.py", line 55, in manhattan_map
    pio.write_image(fig, constants.MANHATTAN_MAP_FILE_PATH)
  File "/Users/jairusmartinez/Documents/Python_Data_Analysis/dagsteru/.venv/lib/python3.12/site-packages/plotly/io/_kaleido.py", line 266, in write_image
    img_data = to_image(
               ^^^^^^^^^
  File "/Users/jairusmartinez/Documents/Python_Data_Analysis/dagsteru/.venv/lib/python3.12/site-packages/plotly/io/_kaleido.py", line 132, in to_image
    raise ValueError(
[0m
